<?xml version="1.0" encoding="UTF-8" ?>

<robot xmlns:xacro="http://ros.org/wiki/xacro" name="spider">

    <!-- Link properties -->
    <!-- <xacro:property name="pi" value="3.1415926535897931"/> -->
    <xacro:property name="body_length_x" value="0.3556"/>
    <xacro:property name="body_length_y" value="0.165"/>
    <xacro:property name="coxa_length" value="0.052"/>
    <xacro:property name="femur_length" value="0.082"/>
    <xacro:property name="tibia_length" value="0.155"/>
    <xacro:property name="tarsus_length" value="0.0"/>

    <!-- Joint properties -->
    <xacro:property name="joint_lower_limit" value="-2.00"/>
    <xacro:property name="joint_upper_limit" value="2.00"/>
    <xacro:property name="joint_effort" value="0.8"/>
    <xacro:property name="joint_velocity" value="0.524"/>

    <!-- Link 0 -->
    <link name="base_link"/>

    <joint name="base_joint" type="fixed">
        <parent link="base_link"/>
        <child link="body_link"/>
        <origin xyz="0.0 0.0 0.0" rpy="0.0 0.0 0.0"/>
    </joint>

    <!-- Link Body -->
    <link name="body_link">
        <visual>
            <origin xyz="0.0 0.0 0.0" rpy="0.0 0.0 0.0"/>
            <geometry>
                <mesh filename="package://spider_description/meshes/base_link.STL" />
            </geometry>
            <material name="">
                <color rgba="0.7 0.7 0.7 1"/>
            </material>
        </visual>
        <collision>
            <origin xyz="0.0 0.0 0.0" rpy="0.0 0.0 0.0"/>
            <geometry>
                <mesh filename="package://spider_description/meshes/base_link.STL" />
            </geometry>
            <material name="">
                <color rgba="0.7 0.7 0.7 1"/>
            </material>
        </collision>
        <inertial>
        <origin
            xyz="-0.000530634264644336 -0.000146735871100936 0.002797336519253"
            rpy="0 0 0" />
        <mass
            value="0.611606451626775" />
        <inertia
            ixx="0.00454780272495035"
            ixy="-5.85469596986661E-07"
            ixz="5.809136780602E-06"
            iyy="0.00784053245943273"
            iyz="1.609753583614E-06"
            izz="0.0121391274208026" />
        </inertial>
    </link>


    <!-- Leg macro -->
    <xacro:macro name="leg" params="side position x y angle axis_coxa axis_femur axis_tibia mass">

        <!-- leg position -->
        <joint name="leg_center_joint_${side}${position}" type="fixed">
            <origin xyz="${x} ${y} 0.0" rpy="0.0 0.0 0.0"/>
            <parent link="body_link"/>
            <child link="leg_center_${side}${position}"/>
        </joint>
        <link name="leg_center_${side}${position}">
            <inertial>
                <origin xyz="0.0 0.0 0.0" rpy="0.0 0.0 0.0" />
                <mass value="0.00001"/>
                <inertia
                    ixx="1.0" ixy="0.0"  ixz="0.0"
                    iyy="1.0" iyz="0.0"
                    izz="1.0" />
            </inertial>
        </link>

        <!-- coxa -->
       <joint name="joint_coxa_${side}${position}" type="revolute">
           <origin xyz="0.0 0.0 0.0" rpy="0.0 0.0 ${angle}"/>
           <parent link="leg_center_${side}${position}"/>
           <child link="link_coxa_${side}${position}"/>
           <axis xyz="0.0 0.0 ${axis_coxa}"/>
           <limit lower="${joint_lower_limit}" upper="${joint_upper_limit}" effort="${joint_effort}" velocity="${joint_velocity}"/>
       </joint>

       <link name="link_coxa_${side}${position}">
           <visual>
               <origin xyz="0.0 0.0 0.0" rpy="0.0 0.0 0.0"/>
               <geometry>
                   <mesh filename="package://spider_description/meshes/coxa_link.STL"/>
               </geometry>
               <material name="">
                   <color rgba="0.7 0.7 0.7 1"/>
               </material>
           </visual>
           <collision>
               <origin xyz="0.0 0.0 0.0" rpy="0.0 0.0 0.0" />
               <geometry>
                   <mesh filename="package://spider_description/meshes/coxa_link.STL"/>
               </geometry>
               <material name="">
                   <color rgba="0.7 0.7 0.7 1" />
               </material>
           </collision>
           <inertial>
           <origin
                   xyz="0.0259999991636717 5.48568285269058E-07 -5.52350892489561E-07"
                   rpy="0 0 0" />
                 <mass
                   value="${mass}" />
                 <inertia
                   ixx="7.12966880670217E-06"
                   ixy="-4.04797875390301E-11"
                   ixz="-4.20782143594676E-11"
                   iyy="7.05736504437165E-06"
                   iyz="-7.44539286286323E-15"
                   izz="7.05736451070854E-06" />
           </inertial>
       </link>

        <!-- femur -->
        <joint name="joint_femur_${side}${position}" type="revolute">
            <origin xyz="${coxa_length} 0.0 0.0" rpy="${pi/2} 0 0.0"/>
            <parent link="link_coxa_${side}${position}"/>
            <child link="link_femur_${side}${position}"/>
            <axis xyz="0.0 0.0 ${axis_femur}"/>
            <limit lower="${joint_lower_limit}" upper="${joint_upper_limit}" effort="${joint_effort}" velocity="${joint_velocity}"/>
        </joint>

        <link name="link_femur_${side}${position}">
            <visual>
                <origin xyz="0.0 0.0 0.0" rpy="0.0 0.0 0.0"/>
                <geometry>
                    <mesh filename="package://spider_description/meshes/2.STL"/>
                </geometry>
                <material name="">
                    <color rgba="0.7 0.7 0.7 1"/>
                </material>
            </visual>
            <collision>
                <origin xyz="0.0 0.0 0.0" rpy="0.0 0.0 0.0" />
                <geometry>
                    <mesh filename="package://spider_description/meshes/2.STL"/>
                </geometry>
                <material name="">
                    <color rgba="0.7 0.7 0.7 1" />
                </material>
            </collision>
            <inertial>
            <origin
                xyz="0.040999769634667 -4.30568319366442E-08 0.000754475780533559"
                rpy="0 0 0" />
            <mass
                value="0.0953381260317791" />
            <inertia
                ixx="1.58226170549124E-05"
                ixy="7.18370173005665E-09"
                ixz="2.44292687080875E-07"
                iyy="9.74932250427542E-05"
                iyz="-1.77284495331422E-11"
                izz="9.24662892423645E-05" />
            </inertial>
        </link>

        <!-- tibia -->
        <joint name="joint_tibia_${side}${position}" type="revolute">
          <origin xyz="${femur_length} 0.0  0.0" rpy="0.0 0.0 0.0"/>
          <parent link="link_femur_${side}${position}"/>
          <child link="link_tibia_${side}${position}"/>
          <axis xyz="0.0 0.0 ${axis_tibia}"/>
          <limit lower="${joint_lower_limit}" upper="${joint_upper_limit}" effort="${joint_effort}" velocity="${joint_velocity}"/>
        </joint>
      
        <link name="link_tibia_${side}${position}">
            <visual>
                <origin xyz="0.0 0.0 0.0" rpy="0.0 0.0 0.0"/>
                <geometry>
                    <mesh filename="package://spider_description/meshes/tibia_link.STL"/>
                </geometry>
                <material name="">
                    <color rgba="0.7 0.7 0.7 1"/>
                </material>
            </visual>
            <collision>
                <origin xyz="0.0 0.0 0.0" rpy="0.0 0.0 0.0" />
                <geometry>
                    <mesh filename="package://spider_description/meshes/tibia_link.STL"/>
                </geometry>
                <material name="">
                    <color rgba="0.7 0.7 0.7 1" />
                </material>
            </collision>
            <inertial>
            <origin
                xyz="0.0582130928710533 -4.8413205307532E-07 -0.000309754397326167"
                rpy="0 0 0" />
            <mass
                value="0.0274685501932791" />
            <inertia
                ixx="1.3790756851875E-05"
                ixy="1.86386884764665E-09"
                ixz="-2.70792447948708E-09"
                iyy="8.67578889959408E-05"
                iyz="1.52160816187718E-13"
                izz="7.87024641434495E-05" />
            </inertial>
        </link>


        <!-- foot -->
        <joint name="foot_joint_${side}${position}" type="fixed">
            <origin xyz="${tibia_length} 0.0 0.0" rpy="0.0 0.0 0.0" />
            <parent link="link_tibia_${side}${position}" />
            <child link="foot_${side}${position}" />
        </joint>
        <link name="foot_${side}${position}">
            <inertial>
                <origin xyz="0.0 0.0 0.0" rpy="0.0 0.0 0.0" />
                <mass value="0.00000001"/>
                <inertia
                    ixx="0.01E-020" ixy="0.0"  ixz="0.0"
                    iyy="0.01E-020" iyz="0.0"
                    izz="0.01E-020" />
            </inertial>
        </link>
    </xacro:macro>

    


<xacro:leg side="r" position="r" x="-0.170" y="-0.110" angle="-${pi*3/4}" axis_femur="1" axis_tibia="1" axis_coxa="1" mass="0.0207333939617734"/>
<xacro:leg side="r" position="m" x="0.0" y="-0.1325" angle="-${pi/2}" axis_femur="1" axis_tibia="1" axis_coxa="1" mass="0.0207333939617734"/>
<xacro:leg side="r" position="f" x="0.170" y="-0.110" angle="-${pi/4}" axis_femur="1" axis_tibia="1" axis_coxa="1" mass="0.04073339396177341"/>

<xacro:leg side="l" position="r" x="-0.170" y="0.110" angle="${pi*3/4}" axis_femur="1" axis_tibia="1" axis_coxa="-1" mass="0.0207333939617734"/>
<xacro:leg side="l" position="m" x="0.0" y="0.1325" angle="${pi/2}" axis_femur="1" axis_tibia="1" axis_coxa="-1" mass="0.0207333939617734"/>
<xacro:leg side="l" position="f" x="0.170" y="0.110" angle="${pi/4}" axis_femur="1" axis_tibia="1" axis_coxa="-1" mass="0.04073339396177341"/>


</robot>
